Workbook

Sheet Disaster_DB
A1: Record_ID | B1: Report_Date | C1: Region | D1: Province | E1: Disaster_Type | F1: Affected_Districts_Count | G1: District_Names | H1: Affected_Subdistricts_Count | I1: Affected_Villages_Count | J1: Affected_Households | K1: Casualties_Deaths | L1: Water_Level_Trend | M1: Current_Status | N1: Remarks | O1: Ingested_At | P1: Source_URL
A2: 2026-10-02_พิษณุโลก_อุทกภัย | B2: 46297 | C2: ภาคเหนือ | D2: พิษณุโลก | E2: อุทกภัย | F2: 1 | G2: อ.บางระกำ | H2: 2 | I2: 2 | J2: 3 | K2: - | L2: ลดลง | M2: กำลังประสบภัย | N2: ปภ. รายงาน 549/2569 วันที่ 2 ต.ค. 2569 เวลา 06.00 น. ตารางหน้า 1; บาดเจ็บ: -; สูญหาย: -; คงเครื่องหมาย - และช่องว่างตามต้นฉบับ ปภ. | O2: 46297.413 | P2: https://direct.disaster.go.th/directing/home
A3: 2026-10-02_เพชรบูรณ์_อุทกภัย | B3: 46297 | C3: ภาคเหนือ | D3: เพชรบูรณ์ | E3: อุทกภัย | F3: 6 | G3: อ.เมืองฯ อ.ชนแดน อ.บึงสามพัน อ.วิเชียรบุรี อ.ศรีเทพ อ.หนองไผ่ | H3: 9 | I3: 19 | J3: 82 | K3: - | L3: ลดลง | M3: กำลังประสบภัย | N3: ปภ. รายงาน 549/2569 วันที่ 2 ต.ค. 2569 เวลา 06.00 น. ตารางหน้า 1; บาดเจ็บ: -; สูญหาย: -; คงเครื่องหมาย - และช่องว่างตามต้นฉบับ ปภ. | O3: 46297.413 | P3: https://direct.disaster.go.th/directing/home
A4: 2026-10-02_กำแพงเพชร_อุทกภัย | B4: 46297 | C4: ภาคเหนือ | D4: กำแพงเพชร | E4: อุทกภัย | F4: 2 | G4: อ.ขาณุวรลักษบุรี อ.คลองขลุง | H4: 21 | I4: 191 | J4: 3128 | K4: - | L4: ลดลง | M4: กำลังประสบภัย | N4: ปภ. รายงาน 549/2569 วันที่ 2 ต.ค. 2569 เวลา 06.00 น. ตารางหน้า 2; บาดเจ็บ: -; สูญหาย: -; คงเครื่องหมาย - และช่องว่างตามต้นฉบับ ปภ. | O4: 46297.413 | P4: https://direct.disaster.go.th/directing/home
A5: 2026-10-02_นครสวรรค์_อุทกภัย | B5: 46297 | C5: ภาคเหนือ | D5: นครสวรรค์ | E5: อุทกภัย | F5: 14 | G5: อ.พยุหะคีรี อ.แม่วงก์ อ.ตาคลี อ.ไพศาลี อ.ลาดยาว อ.บรรพตพิสัย อ.เก้าเลี้ยว อ.เมืองฯ อ.ชุมแสง อ.ท่าตะโก อ.ตากฟ้า อ.โกรกพระ อ.ชุมตาบง อ.หนองบัว | H5: 85 | I5: 501 | J5: 11928 | K5: - | L5: เพิ่มขึ้น | M5: กำลังประสบภัย | N5: ปภ. รายงาน 549/2569 วันที่ 2 ต.ค. 2569 เวลา 06.00 น. ตารางหน้า 2; บาดเจ็บ: -; สูญหาย: -; คงเครื่องหมาย - และช่องว่างตามต้นฉบับ ปภ. | O5: 46297.413 | P5: https://direct.disaster.go.th/directing/home
A6: 2026-10-02_อุทัยธานี_อุทกภัย | B6: 46297 | C6: ภาคกลาง | D6: อุทัยธานี | E6: อุทกภัย | F6: 8 | G6: อ.หนองฉาง อ.ห้วยคต อ.สว่างอารมณ์ อ.หนองขาหย่าง อ.บ้านไร่ อ.ลานสัก อ.เมืองฯ อ.ทัพทัน | H6: 56 | I6: 413 | J6: 4785 | K6: - | L6: เพิ่มขึ้น | M6: กำลังประสบภัย | N6: ปภ. รายงาน 549/2569 วันที่ 2 ต.ค. 2569 เวลา 06.00 น. ตารางหน้า 2; บาดเจ็บ: -; สูญหาย: -; คงเครื่องหมาย - และช่องว่างตามต้นฉบับ ปภ. | O6: 46297.413 | P6: https://direct.disaster.go.th/directing/home
A7: 2026-10-02_ลพบุรี_อุทกภัย | B7: 46297 | C7: ภาคกลาง | D7: ลพบุรี | E7: อุทกภัย | F7: 5 | G7: อ.เมืองฯ อ.ท่าหลวง อ.พัฒนานิคม อ.โคกสำโรง อ.บ้านหมี่ | H7: 23 | I7: 84 | J7: 1657 | K7: - | L7: เพิ่มขึ้น | M7: กำลังประสบภัย | N7: ปภ. รายงาน 549/2569 วันที่ 2 ต.ค. 2569 เวลา 06.00 น. ตารางหน้า 2; บาดเจ็บ: -; สูญหาย: -; คงเครื่องหมาย - และช่องว่างตามต้นฉบับ ปภ. | O7: 46297.413 | P7: https://direct.disaster.go.th/directing/home
A8: 2026-10-02_ชัยนาท_อุทกภัย | B8: 46297 | C8: ภาคกลาง | D8: ชัยนาท | E8: อุทกภัย | F8: 7 | G8: อ.เมืองฯ อ.วัดสิงห์ อ.มโนรมย์ อ.สรรพยา อ.หันคา อ.หนองมะโมง อ.สรรคบุรี | H8: 38 | I8: 168 | J8: 1581 | K8: - | L8: เพิ่มขึ้น | M8: กำลังประสบภัย | N8: ปภ. รายงาน 549/2569 วันที่ 2 ต.ค. 2569 เวลา 06.00 น. ตารางหน้า 2; บาดเจ็บ: -; สูญหาย: -; คงเครื่องหมาย - และช่องว่างตามต้นฉบับ ปภ. | O8: 46297.413 | P8: https://direct.disaster.go.th/directing/home
A9: 2026-10-02_สิงห์บุรี_อุทกภัย | B9: 46297 | C9: ภาคกลาง | D9: สิงห์บุรี | E9: อุทกภัย | F9: 3 | G9: อ.อินทร์บุรี อ.พรหมบุรี อ.เมืองฯ | H9: 3 | I9: 11 | J9: 974 | K9: - | L9: เพิ่มขึ้น | M9: กำลังประสบภัย | N9: ปภ. รายงาน 549/2569 วันที่ 2 ต.ค. 2569 เวลา 06.00 น. ตารางหน้า 2; บาดเจ็บ: -; สูญหาย: -; คงเครื่องหมาย - และช่องว่างตามต้นฉบับ ปภ. | O9: 46297.413 | P9: https://direct.disaster.go.th/directing/home
A10: 2026-10-02_สุพรรณบุรี_อุทกภัย | B10: 46297 | C10: ภาคกลาง | D10: สุพรรณบุรี | E10: อุทกภัย | F10: 9 | G10: อ.บางปลาม้า อ.สองพี่น้อง อ.ดอนเจดีย์ อ.ศรีประจันต์ อ.เมืองฯ อ.สามชุก อ.เดิมบางนางบวช อ.อู่ทอง อ.ด่านช้าง | H10: 92 | I10: 667 | J10: 18987 | K10: - | L10: เพิ่มขึ้น | M10: กำลังประสบภัย | N10: ปภ. รายงาน 549/2569 วันที่ 2 ต.ค. 2569 เวลา 06.00 น. ตารางหน้า 2; บาดเจ็บ: -; สูญหาย: -; คงเครื่องหมาย - และช่องว่างตามต้นฉบับ ปภ. | O10: 46297.413 | P10: https://direct.disaster.go.th/directing/home
A11: 2026-10-02_กาญจนบุรี_อุทกภัย | B11: 46297 | C11: ภาคกลาง | D11: กาญจนบุรี | E11: อุทกภัย | F11: 13 | G11: อ.ไทรโยค อ.เลาขวัญ อ.ห้วยกระเจา อ.หนองปรือ อ.พนมทวน อ.ด่านมะขามเตี้ย อ.ท่าม่วง อ.ท่ามะกา อ.บ่อพลอย อ.ศรีสวัสดิ์ อ.ทองผาภูมิ อ.เมืองฯ อ.สังขละบุรี | H11: 90 | I11: 884 | J11: 9635 | K11: 2 | L11: เพิ่มขึ้น | M11: กำลังประสบภัย | N11: ปภ. รายงาน 549/2569 วันที่ 2 ต.ค. 2569 เวลา 06.00 น. ตารางหน้า 3; บาดเจ็บ: -; สูญหาย: -; คงเครื่องหมาย - และช่องว่างตามต้นฉบับ ปภ. | O11: 46297.413 | P11: https://direct.disaster.go.th/directing/home
A12: 2026-10-02_อ่างทอง_อุทกภัย | B12: 46297 | C12: ภาคกลาง | D12: อ่างทอง | E12: อุทกภัย | F12: 5 | G12: อ.ป่าโมก อ.ไชโย อ.วิเศษชัยชาญ อ.เมืองฯ อ.สามโก้ | H12: 33 | I12: 146 | J12: 2009 | K12: - | L12: เพิ่มขึ้น | M12: กำลังประสบภัย | N12: ปภ. รายงาน 549/2569 วันที่ 2 ต.ค. 2569 เวลา 06.00 น. ตารางหน้า 3; บาดเจ็บ: -; สูญหาย: -; คงเครื่องหมาย - และช่องว่างตามต้นฉบับ ปภ. | O12: 46297.413 | P12: https://direct.disaster.go.th/directing/home
A13: 2026-10-02_สระบุรี_อุทกภัย | B13: 46297 | C13: ภาคกลาง | D13: สระบุรี | E13: อุทกภัย | F13: 13 | G13: อ.หนองแซง อ.มวกเหล็ก อ.เมืองฯ อ.วังม่วง อ.แก่งคอย อ.หนองแค อ.พระพุทธบาท อ.หนองโดน อ.วิหารแดง อ.บ้านหม้อ อ.ดอนพุด อ.เสาไห้ อ.เฉลิมพระเกียรติ | H13: 87 | I13: 566 | J13: 5393 | K13: 1 | L13: ลดลง | M13: กำลังประสบภัย | N13: ปภ. รายงาน 549/2569 วันที่ 2 ต.ค. 2569 เวลา 06.00 น. ตารางหน้า 3; บาดเจ็บ: -; สูญหาย: -; คงเครื่องหมาย - และช่องว่างตามต้นฉบับ ปภ. | O13: 46297.413 | P13: https://direct.disaster.go.th/directing/home
A14: 2026-10-02_พระนครศรีอยุธยา_อุทกภัย | B14: 46297 | C14: ภาคกลาง | D14: พระนครศรีอยุธยา | E14: อุทกภัย | F14: 13 | G14: อ.เสนา อ.บางบาล อ.ผักไห่ อ.บางไทร อ.พระนครศรีอยุธยา อ.บางปะอิน อ.บางปะหัน อ.ลาดบัวหลวง อ.นครหลวง อ.วังน้อย อ.อุทัย อ.ท่าเรือ อ.ภาชี | H14: 169 | I14: 1104 | J14: 44865 | K14: 1 | L14: เพิ่มขึ้น | M14: กำลังประสบภัย | N14: ปภ. รายงาน 549/2569 วันที่ 2 ต.ค. 2569 เวลา 06.00 น. ตารางหน้า 3; บาดเจ็บ: -; สูญหาย: -; คงเครื่องหมาย - และช่องว่างตามต้นฉบับ ปภ. | O14: 46297.413 | P14: https://direct.disaster.go.th/directing/home
A15: 2026-10-02_สมุทรปราการ_อุทกภัย | B15: 46297 | C15: ภาคกลาง | D15: สมุทรปราการ | E15: อุทกภัย | F15: 6 | G15: อ.บางเสาธง อ.บางบ่อ อ.บางพลี อ.เมืองฯ อ.พระประแดง อ.พระสมุทรเจดีย์ | H15: 38 | I15: 382 | J15: 307704 | K15: 8 | L15: เพิ่มขึ้น | M15: กำลังประสบภัย | N15: ปภ. รายงาน 549/2569 วันที่ 2 ต.ค. 2569 เวลา 06.00 น. ตารางหน้า 4; บาดเจ็บ: -; สูญหาย: -; คงเครื่องหมาย - และช่องว่างตามต้นฉบับ ปภ. | O15: 46297.413 | P15: https://direct.disaster.go.th/directing/home
A16: 2026-10-02_ปทุมธานี_อุทกภัย | B16: 46297 | C16: ภาคกลาง | D16: ปทุมธานี | E16: อุทกภัย | F16: 7 | G16: อ.ธัญบุรี อ.เมืองฯ อ.สามโคก อ.คลองหลวง อ.ลำลูกกา อ.หนองเสือ อ.ลาดหลุมแก้ว | H16: 29 | I16: 510 | J16: 182290 | K16: - | L16: เพิ่มขึ้น | M16: กำลังประสบภัย | N16: ปภ. รายงาน 549/2569 วันที่ 2 ต.ค. 2569 เวลา 06.00 น. ตารางหน้า 4; บาดเจ็บ: -; สูญหาย: -; คงเครื่องหมาย - และช่องว่างตามต้นฉบับ ปภ. | O16: 46297.413 | P16: https://direct.disaster.go.th/directing/home
A17: 2026-10-02_นนทบุรี_อุทกภัย | B17: 46297 | C17: ภาคกลาง | D17: นนทบุรี | E17: อุทกภัย | F17: 3 | G17: อ.เมืองฯ อ.บางกรวย อ.ปากเกร็ด | H17: 3 | I17: 3 | J17: - | K17: - | L17: เพิ่มขึ้น | M17: กำลังประสบภัย | N17: ปภ. รายงาน 549/2569 วันที่ 2 ต.ค. 2569 เวลา 06.00 น. ตารางหน้า 4; บาดเจ็บ: -; สูญหาย: -; คงเครื่องหมาย - และช่องว่างตามต้นฉบับ ปภ. | O17: 46297.413 | P17: https://direct.disaster.go.th/directing/home
A18: 2026-10-02_นครปฐม_อุทกภัย | B18: 46297 | C18: ภาคกลาง | D18: นครปฐม | E18: อุทกภัย | F18: 7 | G18: อ.เมืองฯ อ.กำแพงแสน อ.นครชัยศรี อ.พุทธมณฑล อ.สามพราน อ.บางเลน อ.ดอนตูม | H18: 105 | I18: 793 | J18: 43687 | K18: - | L18: เพิ่มขึ้น | M18: กำลังประสบภัย | N18: ปภ. รายงาน 549/2569 วันที่ 2 ต.ค. 2569 เวลา 06.00 น. ตารางหน้า 4; บาดเจ็บ: -; สูญหาย: -; คงเครื่องหมาย - และช่องว่างตามต้นฉบับ ปภ. | O18: 46297.413 | P18: https://direct.disaster.go.th/directing/home
A19: 2026-10-02_ราชบุรี_อุทกภัย | B19: 46297 | C19: ภาคกลาง | D19: ราชบุรี | E19: อุทกภัย | F19: 7 | G19: อ.โพธาราม อ.บางแพ อ.เมืองฯ อ.ดำเนินสะดวก อ.บ้านโป่ง อ.วัดเพลง อ.จอมบึง | H19: 42 | I19: 178 | J19: 3663 | K19: - | L19: เพิ่มขึ้น | M19: กำลังประสบภัย | N19: ปภ. รายงาน 549/2569 วันที่ 2 ต.ค. 2569 เวลา 06.00 น. ตารางหน้า 4; บาดเจ็บ: -; สูญหาย: -; คงเครื่องหมาย - และช่องว่างตามต้นฉบับ ปภ. | O19: 46297.413 | P19: https://direct.disaster.go.th/directing/home
A20: 2026-10-02_เพชรบุรี_อุทกภัย | B20: 46297 | C20: ภาคกลาง | D20: เพชรบุรี | E20: อุทกภัย | F20: 1 | G20: อ.แก่งกระจาน | H20: 2 | I20: 3 | J20: 6 | K20: - | L20: เพิ่มขึ้น | M20: กำลังประสบภัย | N20: ปภ. รายงาน 549/2569 วันที่ 2 ต.ค. 2569 เวลา 06.00 น. ตารางหน้า 4; บาดเจ็บ: -; สูญหาย: -; คงเครื่องหมาย - และช่องว่างตามต้นฉบับ ปภ. | O20: 46297.413 | P20: https://direct.disaster.go.th/directing/home
A21: 2026-10-02_นครนายก_อุทกภัย | B21: 46297 | C21: ภาคตะวันออก | D21: นครนายก | E21: อุทกภัย | F21: 4 | G21: อ.ปากพลี อ.เมืองฯ อ.บ้านนา อ.องครักษ์ | H21: 41 | I21: 416 | J21: 49018 | K21: - | L21: เพิ่มขึ้น | M21: กำลังประสบภัย | N21: ปภ. รายงาน 549/2569 วันที่ 2 ต.ค. 2569 เวลา 06.00 น. ตารางหน้า 4; บาดเจ็บ: -; สูญหาย: -; คงเครื่องหมาย - และช่องว่างตามต้นฉบับ ปภ. | O21: 46297.413 | P21: https://direct.disaster.go.th/directing/home
A22: 2026-10-02_ปราจีนบุรี_อุทกภัย | B22: 46297 | C22: ภาคตะวันออก | D22: ปราจีนบุรี | E22: อุทกภัย | F22: 7 | G22: อ.กบินทร์บุรี อ.นาดี อ.ศรีมหาโพธิ อ.เมืองฯ อ.ประจันตคาม อ.บ้านสร้าง อ.ศรีมโหสถ | H22: 61 | I22: 625 | J22: 39977 | K22: - | L22: เพิ่มขึ้น | M22: กำลังประสบภัย | N22: ปภ. รายงาน 549/2569 วันที่ 2 ต.ค. 2569 เวลา 06.00 น. ตารางหน้า 4; บาดเจ็บ: -; สูญหาย: -; คงเครื่องหมาย - และช่องว่างตามต้นฉบับ ปภ. | O22: 46297.413 | P22: https://direct.disaster.go.th/directing/home
A23: 2026-10-02_ฉะเชิงเทรา_อุทกภัย | B23: 46297 | C23: ภาคตะวันออก | D23: ฉะเชิงเทรา | E23: อุทกภัย | F23: 11 | G23: อ.บางน้ำเปรี้ยว อ.พนมสารคาม อ.บางคล้า อ.แปลงยาว อ.ท่าตะเกียบ อ.สนามชัยเขต อ.เมืองฯ อ.บ้านโพธิ์ อ.บางปะกง อ.คลองเขื่อน อ.ราชสาส์น | H23: 89 | I23: 736 | J23: 47959 | K23: - | L23: เพิ่มขึ้น | M23: กำลังประสบภัย | N23: ปภ. รายงาน 549/2569 วันที่ 2 ต.ค. 2569 เวลา 06.00 น. ตารางหน้า 5; บาดเจ็บ: -; สูญหาย: -; คงเครื่องหมาย - และช่องว่างตามต้นฉบับ ปภ. | O23: 46297.413 | P23: https://direct.disaster.go.th/directing/home
A24: 2026-10-02_สระแก้ว_อุทกภัย | B24: 46297 | C24: ภาคตะวันออก | D24: สระแก้ว | E24: อุทกภัย | F24: 2 | G24: อ.อรัญประเทศ อ.เมืองฯ | H24: 4 | I24: 33 | J24: 4373 | K24: 6 | L24: ลดลง | M24: กำลังประสบภัย | N24: ปภ. รายงาน 549/2569 วันที่ 2 ต.ค. 2569 เวลา 06.00 น. ตารางหน้า 5; บาดเจ็บ: -; สูญหาย: -; คงเครื่องหมาย - และช่องว่างตามต้นฉบับ ปภ. | O24: 46297.413 | P24: https://direct.disaster.go.th/directing/home
A25: 2026-10-02_ชลบุรี_อุทกภัย | B25: 46297 | C25: ภาคตะวันออก | D25: ชลบุรี | E25: อุทกภัย | F25: 10 | G25: อ.เมืองฯ อ.สัตหีบ อ.พนัสนิคม อ.ศรีราชา อ.บางละมุง อ.บ้านบึง อ.หนองใหญ่ อ.เกาะจันทร์ อ.พานทอง อ.บ่อทอง | H25: 78 | I25: 354 | J25: 118723 | K25: - | L25: เพิ่มขึ้น | M25: กำลังประสบภัย | N25: ปภ. รายงาน 549/2569 วันที่ 2 ต.ค. 2569 เวลา 06.00 น. ตารางหน้า 5; บาดเจ็บ: -; สูญหาย: -; คงเครื่องหมาย - และช่องว่างตามต้นฉบับ ปภ. | O25: 46297.413 | P25: https://direct.disaster.go.th/directing/home
A26: 2026-10-02_ระยอง_อุทกภัย | B26: 46297 | C26: ภาคตะวันออก | D26: ระยอง | E26: อุทกภัย | F26: 2 | G26: อ.เมืองฯ อ.แกลง | H26: 9 | I26: 73 | J26: 1760 | K26: - | L26: ทรงตัว | M26: กำลังประสบภัย | N26: ปภ. รายงาน 549/2569 วันที่ 2 ต.ค. 2569 เวลา 06.00 น. ตารางหน้า 5; บาดเจ็บ: -; สูญหาย: -; คงเครื่องหมาย - และช่องว่างตามต้นฉบับ ปภ. | O26: 46297.413 | P26: https://direct.disaster.go.th/directing/home
A27: 2026-10-02_จันทบุรี_อุทกภัย | B27: 46297 | C27: ภาคตะวันออก | D27: จันทบุรี | E27: อุทกภัย | F27: 2 | G27: อ.นายายอาม อ.ท่าใหม่ | H27: 10 | I27: 55 | J27: 7460 | K27: 2 | L27: ลดลง | M27: กำลังประสบภัย | N27: ปภ. รายงาน 549/2569 วันที่ 2 ต.ค. 2569 เวลา 06.00 น. ตารางหน้า 5; บาดเจ็บ: -; สูญหาย: -; คงเครื่องหมาย - และช่องว่างตามต้นฉบับ ปภ. | O27: 46297.413 | P27: https://direct.disaster.go.th/directing/home
A28: 2026-10-02_ตราด_อุทกภัย | B28: 46297 | C28: ภาคตะวันออก | D28: ตราด | E28: อุทกภัย | F28: 3 | G28: อ.บ่อไร่ อ.เขาสมิง อ.เมืองฯ | H28: 17 | I28: 138 | J28: 1310 | K28: - | L28: ลดลง | M28: กำลังประสบภัย | N28: ปภ. รายงาน 549/2569 วันที่ 2 ต.ค. 2569 เวลา 06.00 น. ตารางหน้า 5; บาดเจ็บ: -; สูญหาย: -; คงเครื่องหมาย - และช่องว่างตามต้นฉบับ ปภ. | O28: 46297.413 | P28: https://direct.disaster.go.th/directing/home
A29: 2026-10-02_บุรีรัมย์_อุทกภัย | B29: 46297 | C29: ภาคตะวันออกเฉียงเหนือ | D29: บุรีรัมย์ | E29: อุทกภัย | F29: 2 | G29: อ.นางรอง อ.ประโคนชัย | H29: 23 | I29: 199 | J29: 3164 | K29: - | L29: ลดลง | M29: กำลังประสบภัย | N29: ปภ. รายงาน 549/2569 วันที่ 2 ต.ค. 2569 เวลา 06.00 น. ตารางหน้า 5; บาดเจ็บ: -; สูญหาย: -; คงเครื่องหมาย - และช่องว่างตามต้นฉบับ ปภ. | O29: 46297.413 | P29: https://direct.disaster.go.th/directing/home
A30: 2026-10-02_ชัยภูมิ_อุทกภัย | B30: 46297 | C30: ภาคตะวันออกเฉียงเหนือ | D30: ชัยภูมิ | E30: อุทกภัย | F30: 2 | G30: อ.บำเหน็จณรงค์ อ.จัตุรัส | H30: 5 | I30: 8 | J30: 17 | K30: - | L30: ลดลง | M30: กำลังประสบภัย | N30: ปภ. รายงาน 549/2569 วันที่ 2 ต.ค. 2569 เวลา 06.00 น. ตารางหน้า 5; บาดเจ็บ: -; สูญหาย: -; คงเครื่องหมาย - และช่องว่างตามต้นฉบับ ปภ. | O30: 46297.413 | P30: https://direct.disaster.go.th/directing/home
A31: 2026-10-02_สุรินทร์_อุทกภัย | B31: 46297 | C31: ภาคตะวันออกเฉียงเหนือ | D31: สุรินทร์ | E31: อุทกภัย | F31: 2 | G31: อ.พนมดงรัก อ.ปราสาท | H31: 10 | I31: 65 | J31: 200 | K31: - | L31: ลดลง | M31: กำลังประสบภัย | N31: ปภ. รายงาน 549/2569 วันที่ 2 ต.ค. 2569 เวลา 06.00 น. ตารางหน้า 5; บาดเจ็บ: -; สูญหาย: -; คงเครื่องหมาย - และช่องว่างตามต้นฉบับ ปภ. | O31: 46297.413 | P31: https://direct.disaster.go.th/directing/home
A32: 2026-10-02_ยโสธร_อุทกภัย | B32: 46297 | C32: ภาคตะวันออกเฉียงเหนือ | D32: ยโสธร | E32: อุทกภัย | F32: 2 | G32: อ.คำเขื่อนแก้ว อ.ป่าติ้ว | H32: 5 | I32: 12 | J32: 243 | K32: - | L32: ลดลง | M32: กำลังประสบภัย | N32: ปภ. รายงาน 549/2569 วันที่ 2 ต.ค. 2569 เวลา 06.00 น. ตารางหน้า 5; บาดเจ็บ: -; สูญหาย: -; คงเครื่องหมาย - และช่องว่างตามต้นฉบับ ปภ. | O32: 46297.413 | P32: https://direct.disaster.go.th/directing/home
A33: 2026-10-02_กรุงเทพมหานคร_อุทกภัย | B33: 46297 | C33: กรุงเทพมหานคร | D33: กรุงเทพมหานคร | E33: อุทกภัย | F33: - | G33: - | H33: - | I33: - | J33: 329000 | K33: 4 | L33: ลดลง | M33: กำลังประสบภัย | N33: ปภ. รายงาน 549/2569 วันที่ 2 ต.ค. 2569 เวลา 06.00 น. ตารางหน้า 5; บาดเจ็บ: -; สูญหาย: -; คงเครื่องหมาย - และช่องว่างตามต้นฉบับ ปภ. | O33: 46297.413 | P33: https://direct.disaster.go.th/directing/home
A34: 2026-10-01_พิษณุโลก_อุทกภัย | B34: 46296 | C34: ภาคเหนือ | D34: พิษณุโลก | E34: อุทกภัย | F34: 1 | G34: บางระกำ | H34: 2 | I34: 2 | J34: 3 | K34: - | L34: ระดับน้ำลดลง | M34: กำลังประสบภัย | N34: ปภ. รายงาน 548/2569 วันที่ 1 ต.ค. 2569 เวลา 18.00 น. ตารางหน้า 1; บาดเจ็บ: -; สูญหาย: - | O34: 46296.851 | P34: download.pdf
A35: 2026-10-01_เพชรบูรณ์_อุทกภัย | B35: 46296 | C35: ภาคเหนือ | D35: เพชรบูรณ์ | E35: อุทกภัย | F35: 6 | G35: เมืองฯ ชนแดน บึงสามพัน วิเชียรบุรี ศรีเทพ หนองไผ่ | H35: 9 | I35: 19 | J35: 82 | K35: - | L35: ระดับน้ำลดลง | M35: กำลังประสบภัย | N35: ปภ. รายงาน 548/2569 วันที่ 1 ต.ค. 2569 เวลา 18.00 น. ตารางหน้า 1; บาดเจ็บ: -; สูญหาย: - | O35: 46296.851 | P35: download.pdf
A36: 2026-10-01_กำแพงเพชร_อุทกภัย | B36: 46296 | C36: ภาคเหนือ | D36: กำแพงเพชร | E36: อุทกภัย | F36: 2 | G36: ขาณุวรลักษบุรี คลองขลุง | H36: 21 | I36: 191 | J36: 3128 | K36: - | L36: ระดับน้ำลดลง | M36: กำลังประสบภัย | N36: ปภ. รายงาน 548/2569 วันที่ 1 ต.ค. 2569 เวลา 18.00 น. ตารางหน้า 2; บาดเจ็บ: -; สูญหาย: - | O36: 46296.851 | P36: download.pdf
A37: 2026-10-01_นครสวรรค์_อุทกภัย | B37: 46296 | C37: ภาคเหนือ | D37: นครสวรรค์ | E37: อุทกภัย | F37: 14 | G37: พยุหะคีรี แม่วงก์ ตาคลี ไพศาลี ลาดยาว บรรพตพิสัย เก้าเลี้ยว เมืองฯ ชุมแสง ท่าตะโก ตากฟ้า โกรกพระ ชุมตาบง หนองบัว | H37: 85 | I37: 501 | J37: 11928 | K37: - | L37: ระดับน้ำเพิ่มขึ้น | M37: กำลังประสบภัย | N37: ปภ. รายงาน 548/2569 วันที่ 1 ต.ค. 2569 เวลา 18.00 น. ตารางหน้า 2; บาดเจ็บ: -; สูญหาย: - | O37: 46296.851 | P37: download.pdf
A38: 2026-10-01_อุทัยธานี_อุทกภัย | B38: 46296 | C38: ภาคกลาง | D38: อุทัยธานี | E38: อุทกภัย | F38: 8 | G38: หนองฉาง ห้วยคต สว่างอารมณ์ หนองขาหย่าง บ้านไร่ ลานสัก อ.เมืองฯ ทัพทัน | H38: 56 | I38: 413 | J38: 4785 | K38: - | L38: ระดับน้ำเพิ่มขึ้น | M38: กำลังประสบภัย | N38: ปภ. รายงาน 548/2569 วันที่ 1 ต.ค. 2569 เวลา 18.00 น. ตารางหน้า 2; บาดเจ็บ: -; สูญหาย: - | O38: 46296.851 | P38: download.pdf
A39: 2026-10-01_ลพบุรี_อุทกภัย | B39: 46296 | C39: ภาคกลาง | D39: ลพบุรี | E39: อุทกภัย | F39: 5 | G39: เมืองฯ ท่าหลวง พัฒนานิคม โคกสำโรง บ้านหมี่ | H39: 23 | I39: 84 | J39: 1657 | K39: - | L39: ระดับน้ำเพิ่มขึ้น | M39: กำลังประสบภัย | N39: ปภ. รายงาน 548/2569 วันที่ 1 ต.ค. 2569 เวลา 18.00 น. ตารางหน้า 2; บาดเจ็บ: -; สูญหาย: - | O39: 46296.851 | P39: download.pdf
A40: 2026-10-01_ชัยนาท_อุทกภัย | B40: 46296 | C40: ภาคกลาง | D40: ชัยนาท | E40: อุทกภัย | F40: 7 | G40: เมืองฯ วัดสิงห์ มโนรมย์ สรรพยา หันคา หนองมะโมง สรรคบุรี | H40: 38 | I40: 168 | J40: 1581 | K40: - | L40: ระดับน้ำเพิ่มขึ้น | M40: กำลังประสบภัย | N40: ปภ. รายงาน 548/2569 วันที่ 1 ต.ค. 2569 เวลา 18.00 น. ตารางหน้า 2; บาดเจ็บ: -; สูญหาย: - | O40: 46296.851 | P40: download.pdf
...

Sheet Vulnerable_group
A1: เขตสุขภาพ | B1: จังหวัด | C1: จำนวนเด็ก 0-4 ปีทั้งหมด (คน) | D1: จำนวนหญิงตั้งครรภ์ทั้งหมด (คน) | E1: จำนวนผู้สูงอายุ 60 ปีขึ้นไปทั้งหมด (คน) | F1: รวมทั้งหมด
A2: เขตสุขภาพที่ 1 | B2: เชียงใหม่ | C2: 34889 | D2: 1647 | E2: 356071 | F2: =SUM(C2:E2) -> 392607
A3: เขตสุขภาพที่ 1 | B3: เชียงราย | C3: 32927 | D3: 1619 | E3: 262286 | F3: =SUM(C3:E3) -> 296832
A4: เขตสุขภาพที่ 1 | B4: แพร่ | C4: 17979 | D4: 502 | E4: 114352 | F4: =SUM(C4:E4) -> 132833
A5: เขตสุขภาพที่ 1 | B5: น่าน | C5: 14389 | D5: 879 | E5: 115363 | F5: =SUM(C5:E5) -> 130631
A6: เขตสุขภาพที่ 1 | B6: พะเยา | C6: 9702 | D6: 505 | E6: 118441 | F6: =SUM(C6:E6) -> 128648
A7: เขตสุขภาพที่ 1 | B7: ลำปาง | C7: 14220 | D7: 836 | E7: 188404 | F7: =SUM(C7:E7) -> 203460
A8: เขตสุขภาพที่ 1 | B8: ลำพูน | C8: 8027 | D8: 477 | E8: 112547 | F8: =SUM(C8:E8) -> 121051
A9: เขตสุขภาพที่ 1 | B9: แม่ฮ่องสอน | C9: 9249 | D9: 664 | E9: 36227 | F9: =SUM(C9:E9) -> 46140
A10: เขตสุขภาพที่ 2 | B10: ตาก | C10: 24370 | D10: 1947 | E10: 82855 | F10: =SUM(C10:E10) -> 109172
A11: เขตสุขภาพที่ 2 | B11: เพชรบูรณ์ | C11: 22824 | D11: 1550 | E11: 179264 | F11: =SUM(C11:E11) -> 203638
A12: เขตสุขภาพที่ 2 | B12: พิษณุโลก | C12: 17583 | D12: 1039 | E12: 178853 | F12: =SUM(C12:E12) -> 197475
A13: เขตสุขภาพที่ 2 | B13: อุตรดิตถ์ | C13: 9054 | D13: 577 | E13: 104747 | F13: =SUM(C13:E13) -> 114378
... A78: เขตสุขภาพที่ 13 | B78: กรุงเทพมหานคร | C78: 188530 | D78: 48812 | E78: 1335665 | F78: =SUM(C78:E78) -> 1573007

Sheet Dashboard
B1: Disaster Situation Dashboard
B3: Total Affected Provinces | D3: Total Affected Households | F3: Total Fatalities | H3: Total Affected Districts
B4: =IFERROR(__xludf.DUMMYFUNCTION("LET(latest, INDEX(SORT(FILTER(Disaster_DB!B2:B1000, Disaster_DB!B2:B1000<>""""), 1, FALSE), 1), COUNTIFS(Disaster_DB!B2:B1000, latest))"),27.0) -> 27 | D4: =IFERROR(__xludf.DUMMYFUNCTION("LET(latest, INDEX(SORT(FILTER(Disaster_DB!B2:B1000, Disaster_DB!B2:B1000<>""""), 1, FALSE), 1), SUM(ARRAYFORMULA(IF(Disaster_DB!B2:B1000=latest, IFERROR(VALUE(Disaster_DB!J2:J1000), 0), 0))))"),1175292.0) -> 1175292 | F4: =IFERROR(__xludf.DUMMYFUNCTION("LET(latest, INDEX(SORT(FILTER(Disaster_DB!B2:B1000, Disaster_DB!B2:B1000<>""""), 1, FALSE), 1), SUM(ARRAYFORMULA(IF(Disaster_DB!B2:B1000=latest, IFERROR(VALUE(Disaster_DB!K2:K1000), 0), 0))))"),24.0) -> 24 | H4: =IFERROR(__xludf.DUMMYFUNCTION("LET(latest, INDEX(SORT(FILTER(Disaster_DB!B2:B1000, Disaster_DB!B2:B1000<>""""), 1, FALSE), 1), SUM(ARRAYFORMULA(IF(Disaster_DB!B2:B1000=latest, IFERROR(VALUE(Disaster_DB!F2:F1000), 0), 0))))"),162.0) -> 162
B7: Region | C7: Number of Provinces | D7: Total Affected Households | E7: Total Deaths | F7: Rising Water Trend Count | H7: Province | I7: Affected Households
B8: ภาคเหนือ | C8: =COUNTIFS(Disaster_DB!$C$2:$C$123, $B8, Disaster_DB!$B$2:$B$123, MAX(Disaster_DB!$B$2:$B$123)) -> 2 | D8: =SUMIFS(Disaster_DB!$J$2:$J$123, Disaster_DB!$C$2:$C$123, $B8, Disaster_DB!$B$2:$B$123, MAX(Disaster_DB!$B$2:$B$123)) -> 13095 | E8: =SUMIFS(Disaster_DB!$K$2:$K$123, Disaster_DB!$C$2:$C$123, $B8, Disaster_DB!$B$2:$B$123, MAX(Disaster_DB!$B$2:$B$123)) -> 0 | F8: =COUNTIFS(Disaster_DB!$C$2:$C$123, $B8, Disaster_DB!$L$2:$L$123, "เพิ่มขึ้น", Disaster_DB!$B$2:$B$123, MAX(Disaster_DB!$B$2:$B$123)) -> 1 | H8: =IFERROR(__xludf.DUMMYFUNCTION("QUERY(Disaster_DB!A2:P123, ""SELECT D, J WHERE D IS NOT NULL AND B = date '"" & YEAR(MAX(Disaster_DB!$B$2:$B$123)) & ""-"" & TEXT(MONTH(MAX(Disaster_DB!$B$2:$B$123)),""00"") & ""-"" & TEXT(DAY(MAX(Disaster_DB!$B$2:$B$123)),""00"") & ""' ORDER BY J DESC LI"&"MIT 5"", 0)"),"กรุงเทพมหานคร") -> กรุงเทพมหานคร | I8: =IFERROR(__xludf.DUMMYFUNCTION("""COMPUTED_VALUE"""),329000.0) -> 329000
B9: ภาคกลาง | C9: =COUNTIFS(Disaster_DB!$C$2:$C$123, $B9, Disaster_DB!$B$2:$B$123, MAX(Disaster_DB!$B$2:$B$123)) -> 14 | D9: =SUMIFS(Disaster_DB!$J$2:$J$123, Disaster_DB!$C$2:$C$123, $B9, Disaster_DB!$B$2:$B$123, MAX(Disaster_DB!$B$2:$B$123)) -> 550719 | E9: =SUMIFS(Disaster_DB!$K$2:$K$123, Disaster_DB!$C$2:$C$123, $B9, Disaster_DB!$B$2:$B$123, MAX(Disaster_DB!$B$2:$B$123)) -> 12 | F9: =COUNTIFS(Disaster_DB!$C$2:$C$123, $B9, Disaster_DB!$L$2:$L$123, "เพิ่มขึ้น", Disaster_DB!$B$2:$B$123, MAX(Disaster_DB!$B$2:$B$123)) -> 9 | H9: =IFERROR(__xludf.DUMMYFUNCTION("""COMPUTED_VALUE"""),"สมุทรปราการ") -> สมุทรปราการ | I9: =IFERROR(__xludf.DUMMYFUNCTION("""COMPUTED_VALUE"""),223346.0) -> 223346
B10: ภาคตะวันออก | C10: =COUNTIFS(Disaster_DB!$C$2:$C$123, $B10, Disaster_DB!$B$2:$B$123, MAX(Disaster_DB!$B$2:$B$123)) -> 7 | D10: =SUMIFS(Disaster_DB!$J$2:$J$123, Disaster_DB!$C$2:$C$123, $B10, Disaster_DB!$B$2:$B$123, MAX(Disaster_DB!$B$2:$B$123)) -> 282006 | E10: =SUMIFS(Disaster_DB!$K$2:$K$123, Disaster_DB!$C$2:$C$123, $B10, Disaster_DB!$B$2:$B$123, MAX(Disaster_DB!$B$2:$B$123)) -> 8 | F10: =COUNTIFS(Disaster_DB!$C$2:$C$123, $B10, Disaster_DB!$L$2:$L$123, "เพิ่มขึ้น", Disaster_DB!$B$2:$B$123, MAX(Disaster_DB!$B$2:$B$123)) -> 3 | H10: =IFERROR(__xludf.DUMMYFUNCTION("""COMPUTED_VALUE"""),"ปทุมธานี") -> ปทุมธานี | I10: =IFERROR(__xludf.DUMMYFUNCTION("""COMPUTED_VALUE"""),169724.0) -> 169724
B11: ภาคตะวันออกเฉียงเหนือ | C11: =COUNTIFS(Disaster_DB!$C$2:$C$123, $B11, Disaster_DB!$B$2:$B$123, MAX(Disaster_DB!$B$2:$B$123)) -> 3 | D11: =SUMIFS(Disaster_DB!$J$2:$J$123, Disaster_DB!$C$2:$C$123, $B11, Disaster_DB!$B$2:$B$123, MAX(Disaster_DB!$B$2:$B$123)) -> 472 | E11: =SUMIFS(Disaster_DB!$K$2:$K$123, Disaster_DB!$C$2:$C$123, $B11, Disaster_DB!$B$2:$B$123, MAX(Disaster_DB!$B$2:$B$123)) -> 0 | F11: =COUNTIFS(Disaster_DB!$C$2:$C$123, $B11, Disaster_DB!$L$2:$L$123, "เพิ่มขึ้น", Disaster_DB!$B$2:$B$123, MAX(Disaster_DB!$B$2:$B$123)) -> 0 | H11: =IFERROR(__xludf.DUMMYFUNCTION("""COMPUTED_VALUE"""),"ชลบุรี") -> ชลบุรี | I11: =IFERROR(__xludf.DUMMYFUNCTION("""COMPUTED_VALUE"""),118723.0) -> 118723
B12: กรุงเทพมหานคร | C12: =COUNTIFS(Disaster_DB!$C$2:$C$123, $B12, Disaster_DB!$B$2:$B$123, MAX(Disaster_DB!$B$2:$B$123)) -> 1 | D12: =SUMIFS(Disaster_DB!$J$2:$J$123, Disaster_DB!$C$2:$C$123, $B12, Disaster_DB!$B$2:$B$123, MAX(Disaster_DB!$B$2:$B$123)) -> 329000 | E12: =SUMIFS(Disaster_DB!$K$2:$K$123, Disaster_DB!$C$2:$C$123, $B12, Disaster_DB!$B$2:$B$123, MAX(Disaster_DB!$B$2:$B$123)) -> 4 | F12: =COUNTIFS(Disaster_DB!$C$2:$C$123, $B12, Disaster_DB!$L$2:$L$123, "เพิ่มขึ้น", Disaster_DB!$B$2:$B$123, MAX(Disaster_DB!$B$2:$B$123)) -> 0 | H12: =IFERROR(__xludf.DUMMYFUNCTION("""COMPUTED_VALUE"""),"ฉะเชิงเทรา") -> ฉะเชิงเทรา | I12: =IFERROR(__xludf.DUMMYFUNCTION("""COMPUTED_VALUE"""),54647.0) -> 54647

Sheet BKK_water_DB
A1: station_id | B1: station_code | C1: station_name | D1: district_or_area | E1: canal | F1: latitude | G1: longitude | H1: observed_at_th | I1: water_in_m_msl | J1: water_out01_m_msl | K1: water_out02_m_msl | L1: warning_in_source | M1: critical_in_source | N1: flood_status_source | O1: sensor_status_source | P1: flood_status_code | Q1: sensor_status_code | R1: age_minutes_at_fetch | S1: freshness_at_fetch | T1: has_minus99_source | U1: fetched_at_th | V1: source_url | W1: raw_station_json
A2: THAIWATER:153 | B2: WL.PSC.04 | C2: ค.ภาษีเจริญ-ค.มหาศร | D2: หนองแขม | F2: 13.68138 | G2: 100.35047 | H2: 2021-01-22T12:05:00+07:00 | I2: 0.12 | N2: ไม่ทราบ | O2: ไม่ทราบ | R2: 2995372.6 | S2: ข้อมูลเก่าเกิน 48 ชม. | T2: FALSE | U2: 2026-10-03T14:57:33+07:00 | V2: https://api-v3.thaiwater.net/api/v1/thaiwater30/public/canal_waterlevel | W2: {"canal_datetime":"2021-01-22 12:05","canal_value":0.12,"canal_out":0,"agency":{"agency_name":{"th":"สำนักการระบายน้ำ กรุงเทพมหานคร","en":"Department of Bangkok","jp":""}},"geocode":{"area_code":"1","area_name":{"th":"กรุงเทพมหานคร","en":"Bangkok"},"amphoe_name":{"th":"หนองแขม","en":"Nong Khaem District"},"tumbon_name":{"th":"หนองแขม","en":"Nong Khaem"},"province_code":"10","province_name":{"th":"กรุงเทพมหานคร","en":"Bangkok"}},"station":{"id":153,"canal_name":{"th":"ค.ภาษีเจริญ-ค.มหาศร"},"canal_lat":13.68138,"canal_long":100.35047,"canal_oldcode":"WL.PSC.04","bank":null,"warning_level":null,"critical_level":null}}
A3: THAIWATER:218 | B3: WL.LBK.02 | C3: ค.ลาดบัวขาว ถ.เคหะร่มเกล้า | D3: สะพานสูง | F3: 13.76991 | G3: 100.71494 | H3: 2026-09-28T13:20:00+07:00 | I3: 0.95 | L3: 0.3 | M3: 0.4 | N3: ไม่ทราบ | O3: ไม่ทราบ | R3: 7297.6 | S3: ข้อมูลเก่าเกิน 48 ชม. | T3: FALSE | U3: 2026-10-03T14:57:33+07:00 | V3: https://api-v3.thaiwater.net/api/v1/thaiwater30/public/canal_waterlevel | W3: {"canal_datetime":"2026-09-28 13:20","canal_value":0.95,"canal_out":0,"agency":{"agency_name":{"th":"สำนักการระบายน้ำ กรุงเทพมหานคร","en":"Department of Bangkok","jp":""}},"geocode":{"area_code":"1","area_name":{"th":"กรุงเทพมหานคร","en":"Bangkok"},"amphoe_name":{"th":"สะพานสูง","en":"Saphan Sung District"},"tumbon_name":{"th":"สะพานสูง","en":"Saphan Sung"},"province_code":"10","province_name":{"th":"กรุงเทพมหานคร","en":"Bangkok"}},"station":{"id":218,"canal_name":{"th":"ค.ลาดบัวขาว ถ.เคหะร่มเกล้า"},"canal_lat":13.76991,"canal_long":100.71494,"canal_oldcode":"WL.LBK.02","bank":1,"warning_level":0.3,"critical_level":0.4}}
A4: THAIWATER:185 | B4: WL.LPI.02 | C4: ค.หลุมไผ่ ถ.ประเสริฐมนูกิจ29 | D4: ลาดพร้าว | F4: 13.84703 | G4: 100.6218 | H4: 2026-09-28T13:24:00+07:00 | I4: 1.12 | L4: 0.7 | M4: 0.9 | N4: ไม่ทราบ | O4: ไม่ทราบ | R4: 7293.6 | S4: ข้อมูลเก่าเกิน 48 ชม. | T4: FALSE | U4: 2026-10-03T14:57:33+07:00 | V4: https://api-v3.thaiwater.net/api/v1/thaiwater30/public/canal_waterlevel | W4: {"canal_datetime":"2026-09-28 13:24","canal_value":1.12,"canal_out":0,"agency":{"agency_name":{"th":"สำนักการระบายน้ำ กรุงเทพมหานคร","en":"Department of Bangkok","jp":""}},"geocode":{"area_code":"1","area_name":{"th":"กรุงเทพมหานคร","en":"Bangkok"},"amphoe_name":{"th":"ลาดพร้าว","en":"Lat Phrao District"},"tumbon_name":{"th":"จรเข้บัว","en":"Chorakhe Bua"},"province_code":"10","province_name":{"th":"กรุงเทพมหานคร","en":"Bangkok"}},"station":{"id":185,"canal_name":{"th":"ค.หลุมไผ่ ถ.ประเสริฐมนูกิจ29"},"canal_lat":13.84703,"canal_long":100.6218,"canal_oldcode":"WL.LPI.02","bank":1.8,"warning_level":0.7,"critical_level":0.9}}
A5: THAIWATER:212 | B5: WL.SSB.05 | C5: ค.แสนแสบ รามคำแหง 9 | D5: บางกะปิ | F5: 13.75228 | G5: 100.60555 | H5: 2023-10-23T11:05:00+07:00 | I5: -0.71 | L5: -0.1 | M5: 0.1 | N5: ไม่ทราบ | O5: ไม่ทราบ | R5: 1549672.6 | S5: ข้อมูลเก่าเกิน 48 ชม. | T5: FALSE | U5: 2026-10-03T14:57:33+07:00 | V5: https://api-v3.thaiwater.net/api/v1/thaiwater30/public/canal_waterlevel | W5: {"canal_datetime":"2023-10-23 11:05","canal_value":-0.71,"canal_out":0,"agency":{"agency_name":{"th":"สำนักการระบายน้ำ กรุงเทพมหานคร","en":"Department of Bangkok","jp":""}},"geocode":{"area_code":"1","area_name":{"th":"กรุงเทพมหานคร","en":"Bangkok"},"amphoe_name":{"th":"บางกะปิ","en":"Bang Kapi District"},"tumbon_name":{"th":"หัวหมาก","en":"Hua Mak"},"province_code":"10","province_name":{"th":"กรุงเทพมหานคร","en":"Bangkok"}},"station":{"id":212,"canal_name":{"th":"ค.แสนแสบ รามคำแหง 9"},"canal_lat":13.75228,"canal_long":100.60555,"canal_oldcode":"WL.SSB.05","bank":2,"warning_level":-0.1,"critical_level":0.1}}
A6: THAIWATER:99 | B6: WL.KKO.01 | C6: ค.เก้า-วัดศรีสุขฯ | D6: คลองสามวา | F6: 13.92055 | G6: 100.79237 | H6: 2026-09-28T13:20:00+07:00 | I6: 1.69 | L6: 1.2 | M6: 1.7 | N6: ไม่ทราบ | O6: ไม่ทราบ | R6: 7297.6 | S6: ข้อมูลเก่าเกิน 48 ชม. | T6: FALSE | U6: 2026-10-03T14:57:33+07:00 | V6: https://api-v3.thaiwater.net/api/v1/thaiwater30/public/canal_waterlevel | W6: {"canal_datetime":"2026-09-28 13:20","canal_value":1.69,"canal_out":0,"agency":{"agency_name":{"th":"สำนักการระบายน้ำ กรุงเทพมหานคร","en":"Department of Bangkok","jp":""}},"geocode":{"area_code":"1","area_name":{"th":"กรุงเทพมหานคร","en":"Bangkok"},"amphoe_name":{"th":"คลองสามวา","en":"Khlong Sam Wa District"},"tumbon_name":{"th":"สามวาตะวันออก","en":"Sam Wa Tawan Ok"},"province_code":"10","province_name":{"th":"กรุงเทพมหานคร","en":"Bangkok"}},"station":{"id":99,"canal_name":{"th":"ค.เก้า-วัดศรีสุขฯ"},"canal_lat":13.92055,"canal_long":100.79237,"canal_oldcode":"WL.KKO.01","bank":1.85,"warning_level":1.2,"critical_level":1.7}}
A7: THAIWATER:80 | B7: WL.KKS.04 | C7: ส.กรุงเกษม | D7: สัมพันธวงศ์ | F7: 13.73035 | G7: 100.5141 | H7: 2026-09-28T13:20:00+07:00 | I7: -0.25 | L7: 2.6 | M7: 2.8 | N7: ไม่ทราบ | O7: ไม่ทราบ | R7: 7297.6 | S7: ข้อมูลเก่าเกิน 48 ชม. | T7: FALSE | U7: 2026-10-03T14:57:33+07:00 | V7: https://api-v3.thaiwater.net/api/v1/thaiwater30/public/canal_waterlevel | W7: {"canal_datetime":"2026-09-28 13:20","canal_value":-0.25,"canal_out":0.86,"agency":{"agency_name":{"th":"สำนักการระบายน้ำ กรุงเทพมหานคร","en":"Department of Bangkok","jp":""}},"geocode":{"area_code":"1","area_name":{"th":"กรุงเทพมหานคร","en":"Bangkok"},"amphoe_name":{"th":"สัมพันธวงศ์","en":"Samphanthawong District"},"tumbon_name":{"th":"ตลาดน้อย","en":"Talat Noi"},"province_code":"10","province_name":{"th":"กรุงเทพมหานคร","en":"Bangkok"}},"station":{"id":80,"canal_name":{"th":"ส.กรุงเกษม"},"canal_lat":13.73035,"canal_long":100.5141,"canal_oldcode":"WL.KKS.04","bank":2.8,"warning_level":2.6,"critical_level":2.8}}
A8: THAIWATER:232 | B8: WL.BTY.01 | C8: ค.บางเตย ถ.นวมินทร์ 66/3 | D8: บึงกุ่ม | F8: 13.8065 | G8: 100.64899 | H8: 2026-09-28T13:20:00+07:00 | I8: 0.91 | L8: 0.4 | M8: 0.5 | N8: ไม่ทราบ | O8: ไม่ทราบ | R8: 7297.6 | S8: ข้อมูลเก่าเกิน 48 ชม. | T8: FALSE | U8: 2026-10-03T14:57:33+07:00 | V8: https://api-v3.thaiwater.net/api/v1/thaiwater30/public/canal_waterlevel | W8: {"canal_datetime":"2026-09-28 13:20","canal_value":0.91,"canal_out":0,"agency":{"agency_name":{"th":"สำนักการระบายน้ำ กรุงเทพมหานคร","en":"Department of Bangkok","jp":""}},"geocode":{"area_code":"1","area_name":{"th":"กรุงเทพมหานคร","en":"Bangkok"},"amphoe_name":{"th":"บึงกุ่ม","en":"Bueng Kum District"},"tumbon_name":{"th":"คลองกุ่ม","en":"Khlong Kum"},"province_code":"10","province_name":{"th":"กรุงเทพมหานคร","en":"Bangkok"}},"station":{"id":232,"canal_name":{"th":"ค.บางเตย ถ.นวมินทร์ 66/3"},"canal_lat":13.8065,"canal_long":100.64899,"canal_oldcode":"WL.BTY.01","bank":1.8,"warning_level":0.4,"critical_level":0.5}}
A9: THAIWATER:225 | B9: WL.RSK.01 | C9: ค.ราษฎร์สามัคคี ถ.เพชรเกษม 63 | D9: บางแค | F9: 13.70339 | G9: 100.39142 | H9: 2026-09-27T00:05:00+07:00 | I9: 0.79 | L9: 0.6 | M9: 0.7 | N9: ไม่ทราบ | O9: ไม่ทราบ | R9: 9532.6 | S9: ข้อมูลเก่าเกิน 48 ชม. | T9: FALSE | U9: 2026-10-03T14:57:33+07:00 | V9: https://api-v3.thaiwater.net/api/v1/thaiwater30/public/canal_waterlevel | W9: {"canal_datetime":"2026-09-27 00:05","canal_value":0.79,"canal_out":0,"agency":{"agency_name":{"th":"สำนักการระบายน้ำ กรุงเทพมหานคร","en":"Department of Bangkok","jp":""}},"geocode":{"area_code":"1","area_name":{"th":"กรุงเทพมหานคร","en":"Bangkok"},"amphoe_name":{"th":"บางแค","en":"Bang Khae District"},"tumbon_name":{"th":"หลักสอง","en":"Lak Song"},"province_code":"10","province_name":{"th":"กรุงเทพมหานคร","en":"Bangkok"}},"station":{"id":225,"canal_name":{"th":"ค.ราษฎร์สามัคคี ถ.เพชรเกษม 63"},"canal_lat":13.70339,"canal_long":100.39142,"canal_oldcode":"WL.RSK.01","bank":1.85,"warning_level":0.6,"critical_level":0.7}}
A10: THAIWATER:256 | B10: WL.SBR.02 | C10: ค.บางขุนศรีบุรีรักษ์ ถ.บรมราชชนนี | D10: ทวีวัฒนา | F10: 13.78651 | G10: 100.37053 | H10: 2026-09-28T13:20:00+07:00 | I10: 0.82 | L10: 0.9 | M10: 1 | N10: ไม่ทราบ | O10: ไม่ทราบ | R10: 7297.6 | S10: ข้อมูลเก่าเกิน 48 ชม. | T10: FALSE | U10: 2026-10-03T14:57:33+07:00 | V10: https://api-v3.thaiwater.net/api/v1/thaiwater30/public/canal_waterlevel | W10: {"canal_datetime":"2026-09-28 13:20","canal_value":0.82,"canal_out":0,"agency":{"agency_name":{"th":"สำนักการระบายน้ำ กรุงเทพมหานคร","en":"Department of Bangkok","jp":""}},"geocode":{"area_code":"1","area_name":{"th":"กรุงเทพมหานคร","en":"Bangkok"},"amphoe_name":{"th":"ทวีวัฒนา","en":"Thawi Watthana District"},"tumbon_name":{"th":"ศาลาธรรมสพน์","en":"Sala Thammasop"},"province_code":"10","province_name":{"th":"กรุงเทพมหานคร","en":"Bangkok"}},"station":{"id":256,"canal_name":{"th":"ค.บางขุนศรีบุรีรักษ์ ถ.บรมราชชนนี"},"canal_lat":13.78651,"canal_long":100.37053,"canal_oldcode":"WL.SBR.02","bank":1.1,"warning_level":0.9,"critical_level":1}}
A11: THAIWATER:275 | B11: WL.KKS.03 | C11: ค.ผดุงกรุงเกษม หัวลำโพง | D11: ปทุมวัน | F11: 13.74126 | G11: 100.51582 | H11: 2026-09-28T13:20:00+07:00 | I11: -0.28 | L11: 0.6 | M11: 0.7 | N11: ไม่ทราบ | O11: ไม่ทราบ | R11: 7297.6 | S11: ข้อมูลเก่าเกิน 48 ชม. | T11: FALSE | U11: 2026-10-03T14:57:33+07:00 | V11: https://api-v3.thaiwater.net/api/v1/thaiwater30/public/canal_waterlevel | W11: {"canal_datetime":"2026-09-28 13:20","canal_value":-0.28,"canal_out":0,"agency":{"agency_name":{"th":"สำนักการระบายน้ำ กรุงเทพมหานคร","en":"Department of Bangkok","jp":""}},"geocode":{"area_code":"1","area_name":{"th":"กรุงเทพมหานคร","en":"Bangkok"},"amphoe_name":{"th":"ปทุมวัน","en":"Pathum Wan District"},"tumbon_name":{"th":"รองเมือง","en":"Rong Mueang"},"province_code":"10","province_name":{"th":"กรุงเทพมหานคร","en":"Bangkok"}},"station":{"id":275,"canal_name":{"th":"ค.ผดุงกรุงเกษม หัวลำโพง"},"canal_lat":13.74126,"canal_long":100.51582,"canal_oldcode":"WL.KKS.03","bank":1,"warning_level":0.6,"critical_level":0.7}}
A12: THAIWATER:148 | B12: WL.RMT.01 | C12: ส.คลองพระยาราชมนตรี | D12: บางขุนเทียน | F12: 13.62817 | G12: 100.43914 | H12: 2026-09-28T13:20:00+07:00 | I12: -0.75 | L12: 1 | M12: 1.2 | N12: ไม่ทราบ | O12: ไม่ทราบ | R12: 7297.6 | S12: ข้อมูลเก่าเกิน 48 ชม. | T12: FALSE | U12: 2026-10-03T14:57:33+07:00 | V12: https://api-v3.thaiwater.net/api/v1/thaiwater30/public/canal_waterlevel | W12: {"canal_datetime":"2026-09-28 13:20","canal_value":-0.75,"canal_out":1,"agency":{"agency_name":{"th":"สำนักการระบายน้ำ กรุงเทพมหานคร","en":"Department of Bangkok","jp":""}},"geocode":{"area_code":"1","area_name":{"th":"กรุงเทพมหานคร","en":"Bangkok"},"amphoe_name":{"th":"บางขุนเทียน","en":"Bang Khun Thian District"},"tumbon_name":{"th":"แสมดำ","en":"Samae Dam"},"province_code":"10","province_name":{"th":"กรุงเทพมหานคร","en":"Bangkok"}},"station":{"id":148,"canal_name":{"th":"ส.คลองพระยาราชมนตรี"},"canal_lat":13.62817,"canal_long":100.43914,"canal_oldcode":"WL.RMT.01","bank":1.98,"warning_level":1,"critical_level":1.2}}
A13: THAIWATER:155 | B13: WL.SNC.01 | C13: ส.คลองสนามชัย | D13: บางขุนเทียน | F13: 13.63806 | G13: 100.44765 | H13: 2026-09-28T13:20:00+07:00 | I13: -0.26 | L13: 1 | M13: 1.2 | N13: ไม่ทราบ | O13: ไม่ทราบ | R13: 7297.6 | S13: ข้อมูลเก่าเกิน 48 ชม. | T13: FALSE | U13: 2026-10-03T14:57:33+07:00 | V13: https://api-v3.thaiwater.net/api/v1/thaiwater30/public/canal_waterlevel | W13: {"canal_datetime":"2026-09-28 13:20","canal_value":-0.26,"canal_out":1.2,"agency":{"agency_name":{"th":"สำนักการระบายน้ำ กรุงเทพมหานคร","en":"Department of Bangkok","jp":""}},"geocode":{"area_code":"1","area_name":{"th":"กรุงเทพมหานคร","en":"Bangkok"},"amphoe_name":{"th":"บางขุนเทียน","en":"Bang Khun Thian District"},"tumbon_name":{"th":"ท่าข้าม","en":"Tha Kham"},"province_code":"10","province_name":{"th":"กรุงเทพมหานคร","en":"Bangkok"}},"station":{"id":155,"canal_name":{"th":"ส.คลองสนามชัย"},"canal_lat":13.63806,"canal_long":100.44765,"canal_oldcode":"WL.SNC.01","bank":1.98,"warning_level":1,"critical_level":1.2}}
A14: THAIWATER:46 | B14: WL.BJK.04 | C14: ค.บางจาก ถ.พุทธฯสาย 2 | D14: บางแค | F14: 13.71484 | G14: 100.39596 | H14: 2026-09-28T13:20:00+07:00 | I14: 0.64 | L14: 0.6 | M14: 0.7 | N14: ไม่ทราบ | O14: ไม่ทราบ | R14: 7297.6 | S14: ข้อมูลเก่าเกิน 48 ชม. | T14: FALSE | U14: 2026-10-03T14:57:33+07:00 | V14: https://api-v3.thaiwater.net/api/v1/thaiwater30/public/canal_waterlevel | W14: {"canal_datetime":"2026-09-28 13:20","canal_value":0.64,"canal_out":0,"agency":{"agency_name":{"th":"สำนักการระบายน้ำ กรุงเทพมหานคร","en":"Department of Bangkok","jp":""}},"geocode":{"area_code":"1","area_name":{"th":"กรุงเทพมหานคร","en":"Bangkok"},"amphoe_name":{"th":"บางแค","en":"Bang Khae District"},"tumbon_name":{"th":"บางแคเหนือ","en":"Bang Khae Nuea"},"province_code":"10","province_name":{"th":"กรุงเทพมหานคร","en":"Bangkok"}},"station":{"id":46,"canal_name":{"th":"ค.บางจาก ถ.พุทธฯสาย 2 "},"canal_lat":13.71484,"canal_long":100.39596,"canal_oldcode":"WL.BJK.04","bank":1.59,"warning_level":0.6,"critical_level":0.7}}
... A19: THAIWATER:199 | B19: WL.CTC.01 | C19: ค.ชวดตาเชียง ส.คลองชวดตาเชียง | D19: ห้วยขวาง | F19: 13.76884 | G19: 100.59302 | H19: 2022-10-04T13:30:00+07:00 | I19: -0.42 | L19: 0.1 | M19: 0.2 | N19: ไม่ทราบ | O19: ไม่ทราบ | R19: 2102487.6 | S19: ข้อมูลเก่าเกิน 48 ชม. | T19: FALSE | U19: 2026-10-03T14:57:33+07:00 | V19: https://api-v3.thaiwater.net/api/v1/thaiwater30/public/canal_waterlevel | W19: {"canal_datetime":"2022-10-04 13:30","canal_value":-0.42,"canal_out":0,"agency":{"agency_name":{"th":"สำนักการระบายน้ำ กรุงเทพมหานคร","en":"Department of Bangkok","jp":""}},"geocode":{"area_code":"1","area_name":{"th":"กรุงเทพมหานคร","en":"Bangkok"},"amphoe_name":{"th":"ห้วยขวาง","en":"Huai Khwang District"},"tumbon_name":{"th":"สามเสนนอก","en":"Sam Sen Nok"},"province_code":"10","province_name":{"th":"กรุงเทพมหานคร","en":"Bangkok"}},"station":{"id":199,"canal_name":{"th":"ค.ชวดตาเชียง ส.คลองชวดตาเชียง"},"canal_lat":13.76884,"canal_long":100.59302,"canal_oldcode":"WL.CTC.01","bank":0.9,"warning_level":0.1,"critical_level":0.2}}
A20: THAIWATER:23 | B20: BK02 | C20: คลองบางเขน ช่วง ถ.ประชาชื่น เขตจตุจักร | D20: เมืองนนทบุรี | F20: 13.849379 | G20: 100.54295 | H20: 2019-12-24T14:38:00+07:00 | I20: 0.186 | N20: ไม่ทราบ | O20: ไม่ทราบ | R20: 3564019.6 | S20: ข้อมูลเก่าเกิน 48 ชม. | T20: FALSE | U20: 2026-10-03T14:57:33+07:00 | V20: https://api-v3.thaiwater.net/api/v1/thaiwater30/public/canal_waterlevel | W20: {"canal_datetime":"2019-12-24 14:38","canal_value":0.186,"canal_out":0,"agency":{"agency_name":{"th":"สำนักการระบายน้ำ กรุงเทพมหานคร","en":"Department of Bangkok","jp":""}},"geocode":{"area_code":"2","area_name":{"th":"ภาคกลาง","en":"Central"},"amphoe_name":{"th":"เมืองนนทบุรี","en":"Mueang Nonthaburi District"},"tumbon_name":{"th":"บางเขน","en":"Bang Khen"},"province_code":"12","province_name":{"th":"นนทบุรี","en":"Nonthaburi"}},"station":{"id":23,"canal_name":{"th":"คลองบางเขน ช่วง ถ.ประชาชื่น เขตจตุจักร"},"canal_lat":13.849379,"canal_long":100.542947,"canal_oldcode":"BK02","bank":null,"warning_level":null,"critical_level":null}}
A21: THAIWATER:18 | B21: LP03 | C21: คลองลาดพร้าวช่วง ซ.เสนานิคม เขตลาดพร้าว | D21: จตุจักร | F21: 13.832213 | G21: 100.5897 | H21: 2019-12-24T14:38:00+07:00 | I21: -0.157 | N21: ไม่ทราบ | O21: ไม่ทราบ | R21: 3564019.6 | S21: ข้อมูลเก่าเกิน 48 ชม. | T21: FALSE | U21: 2026-10-03T14:57:33+07:00 | V21: https://api-v3.thaiwater.net/api/v1/thaiwater30/public/canal_waterlevel | W21: {"canal_datetime":"2019-12-24 14:38","canal_value":-0.157,"canal_out":0,"agency":{"agency_name":{"th":"สำนักการระบายน้ำ กรุงเทพมหานคร","en":"Department of Bangkok","jp":""}},"geocode":{"area_code":"2","area_name":{"th":"ภาคกลาง","en":"Central"},"amphoe_name":{"th":"จตุจักร","en":"Chatuchak District"},"tumbon_name":{"th":"จันทรเกษม","en":"Chantharakasem"},"province_code":"10","province_name":{"th":"กรุงเทพมหานคร","en":"Bangkok"}},"station":{"id":18,"canal_name":{"th":"คลองลาดพร้าวช่วง ซ.เสนานิคม เขตลาดพร้าว"},"canal_lat":13.832213,"canal_long":100.589696,"canal_oldcode":"LP03","bank":null,"warning_level":null,"critical_level":null}}
A22: THAIWATER:7 | B22: LP01 | C22: คลองลาดพร้าวช่วง ถ.ประดิษฐ์มนูธรรม | D22: ห้วยขวาง | F22: 13.759541 | G22: 100.59636 | H22: 2019-12-24T14:38:00+07:00 | I22: -0.301 | N22: ไม่ทราบ | O22: ไม่ทราบ | R22: 3564019.6 | S22: ข้อมูลเก่าเกิน 48 ชม. | T22: FALSE | U22: 2026-10-03T14:57:33+07:00 | V22: https://api-v3.thaiwater.net/api/v1/thaiwater30/public/canal_waterlevel | W22: {"canal_datetime":"2019-12-24 14:38","canal_value":-0.301,"canal_out":0,"agency":{"agency_name":{"th":"สำนักการระบายน้ำ กรุงเทพมหานคร","en":"Department of Bangkok","jp":""}},"geocode":{"area_code":"1","area_name":{"th":"กรุงเทพมหานคร","en":"Bangkok"},"amphoe_name":{"th":"ห้วยขวาง","en":"Huai Khwang District"},"tumbon_name":{"th":"บางกะปิ","en":"Bang Kapi"},"province_code":"10","province_name":{"th":"กรุงเทพมหานคร","en":"Bangkok"}},"station":{"id":7,"canal_name":{"th":"คลองลาดพร้าวช่วง ถ.ประดิษฐ์มนูธรรม"},"canal_lat":13.759541,"canal_long":100.596361,"canal_oldcode":"LP01","bank":null,"warning_level":null,"critical_level":null}}
A23: THAIWATER:17 | B23: KP02 | C23: คลองเปรมประชากร ช่วงวัดเทวสุนทร | D23: จตุจักร | F23: 13.850711 | G23: 100.56088 | H23: 2019-12-24T14:38:00+07:00 | I23: -0.031 | N23: ไม่ทราบ | O23: ไม่ทราบ | R23: 3564019.6 | S23: ข้อมูลเก่าเกิน 48 ชม. | T23: FALSE | U23: 2026-10-03T14:57:33+07:00 | V23: https://api-v3.thaiwater.net/api/v1/thaiwater30/public/canal_waterlevel | W23: {"canal_datetime":"2019-12-24 14:38","canal_value":-0.031,"canal_out":0,"agency":{"agency_name":{"th":"สำนักการระบายน้ำ กรุงเทพมหานคร","en":"Department of Bangkok","jp":""}},"geocode":{"area_code":"1","area_name":{"th":"กรุงเทพมหานคร","en":"Bangkok"},"amphoe_name":{"th":"จตุจักร","en":"Chatuchak District"},"tumbon_name":{"th":"ลาดยาว","en":"Lat Yao"},"province_code":"10","province_name":{"th":"กรุงเทพมหานคร","en":"Bangkok"}},"station":{"id":17,"canal_name":{"th":"คลองเปรมประชากร ช่วงวัดเทวสุนทร"},"canal_lat":13.850711,"canal_long":100.560876,"canal_oldcode":"KP02","bank":null,"warning_level":null,"critical_level":null}}
A24: THAIWATER:14 | B24: SS06 | C24: คลองแสนแสบช่วง ซ.เสรีไทย 24 เขตบึงกุ่ม | D24: บึงกุ่ม | F24: 13.780512 | G24: 100.67385 | H24: 2019-12-24T14:38:00+07:00 | I24: -0.343 | N24: ไม่ทราบ | O24: ไม่ทราบ | R24: 3564019.6 | S24: ข้อมูลเก่าเกิน 48 ชม. | T24: FALSE | U24: 2026-10-03T14:57:33+07:00 | V24: https://api-v3.thaiwater.net/api/v1/thaiwater30/public/canal_waterlevel | W24: {"canal_datetime":"2019-12-24 14:38","canal_value":-0.343,"canal_out":0,"agency":{"agency_name":{"th":"สำนักการระบายน้ำ กรุงเทพมหานคร","en":"Department of Bangkok","jp":""}},"geocode":{"area_code":"1","area_name":{"th":"กรุงเทพมหานคร","en":"Bangkok"},"amphoe_name":{"th":"บึงกุ่ม","en":"Bueng Kum District"},"tumbon_name":{"th":"คลองกุ่ม","en":"Khlong Kum"},"province_code":"10","province_name":{"th":"กรุงเทพมหานคร","en":"Bangkok"}},"station":{"id":14,"canal_name":{"th":"คลองแสนแสบช่วง ซ.เสรีไทย 24 เขตบึงกุ่ม"},"canal_lat":13.780512,"canal_long":100.673845,"canal_oldcode":"SS06","bank":null,"warning_level":null,"critical_level":null}}
A25: THAIWATER:246 | B25: WL.TPK.01 | C25: ค.ลาดกระบัง ซ.ลาดกระบัง 54/6 | D25: ลาดกระบัง | F25: 13.72294 | G25: 100.75193 | H25: 2025-01-24T13:45:00+07:00 | I25: -0.37 | L25: 0.5 | M25: 0.6 | N25: ไม่ทราบ | O25: ไม่ทราบ | R25: 888552.6 | S25: ข้อมูลเก่าเกิน 48 ชม. | T25: FALSE | U25: 2026-10-03T14:57:33+07:00 | V25: https://api-v3.thaiwater.net/api/v1/thaiwater30/public/canal_waterlevel | W25: {"canal_datetime":"2025-01-24 13:45","canal_value":-0.37,"canal_out":0,"agency":{"agency_name":{"th":"สำนักการระบายน้ำ กรุงเทพมหานคร","en":"Department of Bangkok","jp":""}},"geocode":{"area_code":"1","area_name":{"th":"กรุงเทพมหานคร","en":"Bangkok"},"amphoe_name":{"th":"ลาดกระบัง","en":"Lat Krabang District"},"tumbon_name":{"th":"ลาดกระบัง","en":"Lat Krabang"},"province_code":"10","province_name":{"th":"กรุงเทพมหานคร","en":"Bangkok"}},"station":{"id":246,"canal_name":{"th":"ค.ลาดกระบัง ซ.ลาดกระบัง 54/6"},"canal_lat":13.72294,"canal_long":100.75193,"canal_oldcode":"WL.TPK.01","bank":1,"warning_level":0.5,"critical_level":0.6}}
A26: THAIWATER:70 | B26: WL.BSU.01 | C26: ส.คลองบางซื่อ | D26: บางซื่อ | F26: 13.80009 | G26: 100.5184 | H26: 2026-09-28T13:20:00+07:00 | I26: -0.79 | L26: 3.3 | M26: 3.5 | N26: ไม่ทราบ | O26: ไม่ทราบ | R26: 7297.6 | S26: ข้อมูลเก่าเกิน 48 ชม. | T26: FALSE | U26: 2026-10-03T14:57:33+07:00 | V26: https://api-v3.thaiwater.net/api/v1/thaiwater30/public/canal_waterlevel | W26: {"canal_datetime":"2026-09-28 13:20","canal_value":-0.79,"canal_out":1.48,"agency":{"agency_name":{"th":"สำนักการระบายน้ำ กรุงเทพมหานคร","en":"Department of Bangkok","jp":""}},"geocode":{"area_code":"1","area_name":{"th":"กรุงเทพมหานคร","en":"Bangkok"},"amphoe_name":{"th":"บางซื่อ","en":"Bang Sue District"},"tumbon_name":{"th":"บางซื่อ","en":"Bang Sue"},"province_code":"10","province_name":{"th":"กรุงเทพมหานคร","en":"Bangkok"}},"station":{"id":70,"canal_name":{"th":"ส.คลองบางซื่อ"},"canal_lat":13.80009,"canal_long":100.5184,"canal_oldcode":"WL.BSU.01","bank":3.5,"warning_level":3.3,"critical_level":3.5}}
A27: THAIWATER:221 | B27: WL.RKC.01 | C27: ค.ข้างศูนย์ราชการ | D27: หลักสี่ | F27: 13.88457 | G27: 100.56277 | H27: 2026-09-26T16:20:00+07:00 | I27: -0.8 | L27: 0.7 | M27: 0.8 | N27: ไม่ทราบ | O27: ไม่ทราบ | R27: 9997.6 | S27: ข้อมูลเก่าเกิน 48 ชม. | T27: FALSE | U27: 2026-10-03T14:57:33+07:00 | V27: https://api-v3.thaiwater.net/api/v1/thaiwater30/public/canal_waterlevel | W27: {"canal_datetime":"2026-09-26 16:20","canal_value":-0.8,"canal_out":0,"agency":{"agency_name":{"th":"สำนักการระบายน้ำ กรุงเทพมหานคร","en":"Department of Bangkok","jp":""}},"geocode":{"area_code":"1","area_name":{"th":"กรุงเทพมหานคร","en":"Bangkok"},"amphoe_name":{"th":"หลักสี่","en":"Lak Si District"},"tumbon_name":{"th":"ทุ่งสองห้อง","en":"Thung Song Hong"},"province_code":"10","province_name":{"th":"กรุงเทพมหานคร","en":"Bangkok"}},"station":{"id":221,"canal_name":{"th":"ค.ข้างศูนย์ราชการ"},"canal_lat":13.88457,"canal_long":100.56277,"canal_oldcode":"WL.RKC.01","bank":1,"warning_level":0.7,"critical_level":0.8}}
A28: THAIWATER:113 | B28: WL.LPW.02 | C28: ค.ลาดพร้าว-วัดลาดพร้าว | D28: ห้วยขวาง | F28: 13.80293 | G28: 100.58822 | H28: 2026-09-26T00:15:00+07:00 | I28: 0.95 | L28: 0.4 | M28: 0.55 | N28: ไม่ทราบ | O28: ไม่ทราบ | R28: 10962.6 | S28: ข้อมูลเก่าเกิน 48 ชม. | T28: FALSE | U28: 2026-10-03T14:57:33+07:00 | V28: https://api-v3.thaiwater.net/api/v1/thaiwater30/public/canal_waterlevel | W28: {"canal_datetime":"2026-09-26 00:15","canal_value":0.95,"canal_out":0,"agency":{"agency_name":{"th":"สำนักการระบายน้ำ กรุงเทพมหานคร","en":"Department of Bangkok","jp":""}},"geocode":{"area_code":"1","area_name":{"th":"กรุงเทพมหานคร","en":"Bangkok"},"amphoe_name":{"th":"ห้วยขวาง","en":"Huai Khwang District"},"tumbon_name":{"th":"สามเสนนอก","en":"Sam Sen Nok"},"province_code":"10","province_name":{"th":"กรุงเทพมหานคร","en":"Bangkok"}},"station":{"id":113,"canal_name":{"th":"ค.ลาดพร้าว-วัดลาดพร้าว"},"canal_lat":13.80293,"canal_long":100.58822,"canal_oldcode":"WL.LPW.02","bank":1.9,"warning_level":0.4,"critical_level":0.55}}
A29: THAIWATER:71 | B29: WL.SSB.09 | C29: ปตร.คลองแสนแสบ-บางชัน | D29: สะพานสูง | F29: 13.7972 | G29: 100.70458 | H29: 2026-09-28T13:20:00+07:00 | I29: 0.93 | L29: 0.4 | M29: 0.6 | N29: ไม่ทราบ | O29: ไม่ทราบ | R29: 7297.6 | S29: ข้อมูลเก่าเกิน 48 ชม. | T29: FALSE | U29: 2026-10-03T14:57:33+07:00 | V29: https://api-v3.thaiwater.net/api/v1/thaiwater30/public/canal_waterlevel | W29: {"canal_datetime":"2026-09-28 13:20","canal_value":0.93,"canal_out":0.62,"agency":{"agency_name":{"th":"สำนักการระบายน้ำ กรุงเทพมหานคร","en":"Department of Bangkok","jp":""}},"geocode":{"area_code":"1","area_name":{"th":"กรุงเทพมหานคร","en":"Bangkok"},"amphoe_name":{"th":"สะพานสูง","en":"Saphan Sung District"},"tumbon_name":{"th":"สะพานสูง","en":"Saphan Sung"},"province_code":"10","province_name":{"th":"กรุงเทพมหานคร","en":"Bangkok"}},"station":{"id":71,"canal_name":{"th":"ปตร.คลองแสนแสบ-บางชัน"},"canal_lat":13.7972,"canal_long":100.70458,"canal_oldcode":"WL.SSB.09","bank":1.98,"warning_level":0.4,"critical_level":0.6}}
A30: THAIWATER:667 | B30: WL.BNA.04 | C30: ค.บางนา ซ.บางนา-ตราด 56 | D30: บางนา | F30: 13.6594 | G30: 100.64935 | H30: 2026-09-28T13:20:00+07:00 | I30: 0.06 | N30: ไม่ทราบ | O30: ไม่ทราบ | R30: 7297.6 | S30: ข้อมูลเก่าเกิน 48 ชม. | T30: FALSE | U30: 2026-10-03T14:57:33+07:00 | V30: https://api-v3.thaiwater.net/api/v1/thaiwater30/public/canal_waterlevel | W30: {"canal_datetime":"2026-09-28 13:20","canal_value":0.06,"canal_out":0,"agency":{"agency_name":{"th":"สำนักการระบายน้ำ กรุงเทพมหานคร","en":"Department of Bangkok","jp":""}},"geocode":{"area_code":"1","area_name":{"th":"กรุงเทพมหานคร","en":"Bangkok"},"amphoe_name":{"th":"บางนา","en":"Bang Na District"},"tumbon_name":{"th":"บางนา","en":"Bang Na"},"province_code":"10","province_name":{"th":"กรุงเทพมหานคร","en":"Bangkok"}},"station":{"id":667,"canal_name":{"th":"ค.บางนา ซ.บางนา-ตราด 56"},"canal_lat":13.6594,"canal_long":100.64935,"canal_oldcode":"WL.BNA.04","bank":null,"warning_level":null,"critical_level":null}}
A31: THAIWATER:114 | B31: WL.LPW.03 | C31: ค.ลาดพร้าว-เสนานิคม | D31: จตุจักร | F31: 13.83224 | G31: 100.58974 | H31: 2026-09-28T13:20:00+07:00 | I31: 1.04 | L31: 0.6 | M31: 0.75 | N31: ไม่ทราบ | O31: ไม่ทราบ | R31: 7297.6 | S31: ข้อมูลเก่าเกิน 48 ชม. | T31: FALSE | U31: 2026-10-03T14:57:33+07:00 | V31: https://api-v3.thaiwater.net/api/v1/thaiwater30/public/canal_waterlevel | W31: {"canal_datetime":"2026-09-28 13:20","canal_value":1.04,"canal_out":0,"agency":{"agency_name":{"th":"สำนักการระบายน้ำ กรุงเทพมหานคร","en":"Department of Bangkok","jp":""}},"geocode":{"area_code":"2","area_name":{"th":"ภาคกลาง","en":"Central"},"amphoe_name":{"th":"จตุจักร","en":"Chatuchak District"},"tumbon_name":{"th":"จันทรเกษม","en":"Chantharakasem"},"province_code":"10","province_name":{"th":"กรุงเทพมหานคร","en":"Bangkok"}},"station":{"id":114,"canal_name":{"th":"ค.ลาดพร้าว-เสนานิคม"},"canal_lat":13.83224,"canal_long":100.58974,"canal_oldcode":"WL.LPW.03","bank":1.9,"warning_level":0.6,"critical_level":0.75}}
A32: THAIWATER:250 | B32: WL.KJN.01 | C32: ค.จั่น ถ.ลาดพร้าว | D32: วังทองหลาง | F32: 13.77609 | G32: 100.62816 | H32: 2026-09-28T13:20:00+07:00 | I32: 0.64 | L32: -0.2 | M32: 0 | N32: ไม่ทราบ | O32: ไม่ทราบ | R32: 7297.6 | S32: ข้อมูลเก่าเกิน 48 ชม. | T32: FALSE | U32: 2026-10-03T14:57:33+07:00 | V32: https://api-v3.thaiwater.net/api/v1/thaiwater30/public/canal_waterlevel | W32: {"canal_datetime":"2026-09-28 13:20","canal_value":0.64,"canal_out":0,"agency":{"agency_name":{"th":"สำนักการระบายน้ำ กรุงเทพมหานคร","en":"Department of Bangkok","jp":""}},"geocode":{"area_code":"1","area_name":{"th":"กรุงเทพมหานคร","en":"Bangkok"},"amphoe_name":{"th":"วังทองหลาง","en":"Wang Thonglang District"},"tumbon_name":{"th":"วังทองหลาง","en":"Wang Thong Lang"},"province_code":"10","province_name":{"th":"กรุงเทพมหานคร","en":"Bangkok"}},"station":{"id":250,"canal_name":{"th":"ค.จั่น ถ.ลาดพร้าว"},"canal_lat":13.77609,"canal_long":100.62816,"canal_oldcode":"WL.KJN.01","bank":1,"warning_level":-0.2,"critical_level":0}}
A33: THAIWATER:55 | B33: WL.BSU.04 | C33: ค.บางซื่อ ถ.พหลฯ | D33: พญาไท | F33: 13.79619 | G33: 100.55035 | H33: 2026-09-28T13:20:00+07:00 | I33: -0.98 | L33: 0.4 | M33: 0.5 | N33: ไม่ทราบ | O33: ไม่ทราบ | R33: 7297.6 | S33: ข้อมูลเก่าเกิน 48 ชม. | T33: FALSE | U33: 2026-10-03T14:57:33+07:00 | V33: https://api-v3.thaiwater.net/api/v1/thaiwater30/public/canal_waterlevel | W33: {"canal_datetime":"2026-09-28 13:20","canal_value":-0.98,"canal_out":0,"agency":{"agency_name":{"th":"สำนักการระบายน้ำ กรุงเทพมหานคร","en":"Department of Bangkok","jp":""}},"geocode":{"area_code":"1","area_name":{"th":"กรุงเทพมหานคร","en":"Bangkok"},"amphoe_name":{"th":"พญาไท","en":"Phaya Thai District"},"tumbon_name":{"th":"สามเสนใน","en":"Sam Sen Nai"},"province_code":"10","province_name":{"th":"กรุงเทพมหานคร","en":"Bangkok"}},"station":{"id":55,"canal_name":{"th":"ค.บางซื่อ ถ.พหลฯ"},"canal_lat":13.79619,"canal_long":100.55035,"canal_oldcode":"WL.BSU.04","bank":1.9,"warning_level":0.4,"critical_level":0.5}}
A34: THAIWATER:89 | B34: WL.BOA.01 | C34: ส.บางอ้อ | D34: พระโขนง | F34: 13.68206 | G34: 100.59226 | H34: 2026-09-28T13:20:00+07:00 | I34: -1.28 | L34: 2.6 | M34: 2.8 | N34: ไม่ทราบ | O34: ไม่ทราบ | R34: 7297.6 | S34: ข้อมูลเก่าเกิน 48 ชม. | T34: FALSE | U34: 2026-10-03T14:57:33+07:00 | V34: https://api-v3.thaiwater.net/api/v1/thaiwater30/public/canal_waterlevel | W34: {"canal_datetime":"2026-09-28 13:20","canal_value":-1.28,"canal_out":0.29,"agency":{"agency_name":{"th":"สำนักการระบายน้ำ กรุงเทพมหานคร","en":"Department of Bangkok","jp":""}},"geocode":{"area_code":"1","area_name":{"th":"กรุงเทพมหานคร","en":"Bangkok"},"amphoe_name":{"th":"พระโขนง","en":"Phra Khanong District"},"tumbon_name":{"th":"บางจาก","en":"Bang Chak"},"province_code":"10","province_name":{"th":"กรุงเทพมหานคร","en":"Bangkok"}},"station":{"id":89,"canal_name":{"th":"ส.บางอ้อ"},"canal_lat":13.68206,"canal_long":100.59226,"canal_oldcode":"WL.BOA.01","bank":2.8,"warning_level":2.6,"critical_level":2.8}}
A35: THAIWATER:277 | B35: WL.KLD.01 | C35: ค.หลอด ส.ปากคลองตลาด | D35: พระนคร | F35: 13.74261 | G35: 100.49492 | H35: 2026-09-28T13:20:00+07:00 | I35: -0.41 | L35: 0.6 | M35: 0.7 | N35: ไม่ทราบ | O35: ไม่ทราบ | R35: 7297.6 | S35: ข้อมูลเก่าเกิน 48 ชม. | T35: FALSE | U35: 2026-10-03T14:57:33+07:00 | V35: https://api-v3.thaiwater.net/api/v1/thaiwater30/public/canal_waterlevel | W35: {"canal_datetime":"2026-09-28 13:20","canal_value":-0.41,"canal_out":0,"agency":{"agency_name":{"th":"สำนักการระบายน้ำ กรุงเทพมหานคร","en":"Department of Bangkok","jp":""}},"geocode":{"area_code":"1","area_name":{"th":"กรุงเทพมหานคร","en":"Bangkok"},"amphoe_name":{"th":"พระนคร","en":"Phra Nakhon District"},"tumbon_name":{"th":"วังบูรพาภิรมย์","en":"Wang Burapha Phirom"},"province_code":"10","province_name":{"th":"กรุงเทพมหานคร","en":"Bangkok"}},"station":{"id":277,"canal_name":{"th":"ค.หลอด ส.ปากคลองตลาด"},"canal_lat":13.74261,"canal_long":100.49492,"canal_oldcode":"WL.KLD.01","bank":1.8,"warning_level":0.6,"critical_level":0.7}}
A36: THAIWATER:65 | B36: WL.TUT.01 | C36: ส.คลองตาอูฐ | D36: หลักสี่ | F36: 13.89975 | G36: 100.58673 | H36: 2025-10-22T14:35:00+07:00 | I36: 0 | L36: 0.6 | M36: 0.7 | N36: ไม่ทราบ | O36: ไม่ทราบ | R36: 498262.6 | S36: ข้อมูลเก่าเกิน 48 ชม. | T36: FALSE | U36: 2026-10-03T14:57:33+07:00 | V36: https://api-v3.thaiwater.net/api/v1/thaiwater30/public/canal_waterlevel | W36: {"canal_datetime":"2025-10-22 14:35","canal_value":0,"canal_out":0.04,"agency":{"agency_name":{"th":"สำนักการระบายน้ำ กรุงเทพมหานคร","en":"Department of Bangkok","jp":""}},"geocode":{"area_code":"1","area_name":{"th":"กรุงเทพมหานคร","en":"Bangkok"},"amphoe_name":{"th":"หลักสี่","en":"Lak Si District"},"tumbon_name":{"th":"ทุ่งสองห้อง","en":"Thung Song Hong"},"province_code":"10","province_name":{"th":"กรุงเทพมหานคร","en":"Bangkok"}},"station":{"id":65,"canal_name":{"th":"ส.คลองตาอูฐ"},"canal_lat":13.89975,"canal_long":100.58673,"canal_oldcode":"WL.TUT.01","bank":1.98,"warning_level":0.6,"critical_level":0.7}}
A37: THAIWATER:19 | B37: KP03 | C37: คลองเปรมประชากร ช่วง สน.ดอนเมือง | D37: ดอนเมือง | F37: 13.938917 | G37: 100.60645 | H37: 2019-12-24T14:38:00+07:00 | I37: 0.288 | N37: ไม่ทราบ | O37: ไม่ทราบ | R37: 3564019.6 | S37: ข้อมูลเก่าเกิน 48 ชม. | T37: FALSE | U37: 2026-10-03T14:57:33+07:00 | V37: https://api-v3.thaiwater.net/api/v1/thaiwater30/public/canal_waterlevel | W37: {"canal_datetime":"2019-12-24 14:38","canal_value":0.288,"canal_out":0,"agency":{"agency_name":{"th":"สำนักการระบายน้ำ กรุงเทพมหานคร","en":"Department of Bangkok","jp":""}},"geocode":{"area_code":"1","area_name":{"th":"กรุงเทพมหานคร","en":"Bangkok"},"amphoe_name":{"th":"ดอนเมือง","en":"Don Mueang District"},"tumbon_name":{"th":"สีกัน","en":"Si Kan"},"province_code":"10","province_name":{"th":"กรุงเทพมหานคร","en":"Bangkok"}},"station":{"id":19,"canal_name":{"th":"คลองเปรมประชากร ช่วง สน.ดอนเมือง"},"canal_lat":13.938917,"canal_long":100.606452,"canal_oldcode":"KP03","bank":null,"warning_level":null,"critical_level":null}}
A38: THAIWATER:1 | B38: PK01 | C38: แม่น้ำเจ้าพระยา บริเวณปากคลองตลาด | D38: พระนคร | F38: 13.7422 | G38: 100.49464 | H38: 2019-12-24T14:38:00+07:00 | I38: 0.426 | N38: ไม่ทราบ | O38: ไม่ทราบ | R38: 3564019.6 | S38: ข้อมูลเก่าเกิน 48 ชม. | T38: FALSE | U38: 2026-10-03T14:57:33+07:00 | V38: https://api-v3.thaiwater.net/api/v1/thaiwater30/public/canal_waterlevel | W38: {"canal_datetime":"2019-12-24 14:38","canal_value":0.426,"canal_out":0,"agency":{"agency_name":{"th":"สำนักการระบายน้ำ กรุงเทพมหานคร","en":"Department of Bangkok","jp":""}},"geocode":{"area_code":"1","area_name":{"th":"กรุงเทพมหานคร","en":"Bangkok"},"amphoe_name":{"th":"พระนคร","en":"Phra Nakhon District"},"tumbon_name":{"th":"วังบูรพาภิรมย์","en":"Wang Burapha Phirom"},"province_code":"10","province_name":{"th":"กรุงเทพมหานคร","en":"Bangkok"}},"station":{"id":1,"canal_name":{"th":"แม่น้ำเจ้าพระยา บริเวณปากคลองตลาด"},"canal_lat":13.7422,"canal_long":100.49464,"canal_oldcode":"PK01","bank":null,"warning_level":null,"critical_level":null}}
A39: THAIWATER:5 | B39: SS01 | C39: คลองแสนแสบ ช่วง ค.ผดุงกรุงเกษม (โบ้เบ้) | D39: ปทุมวัน | F39: 13.752819 | G39: 100.51719 | H39: 2019-12-24T14:38:00+07:00 | I39: -0.164 | N39: ไม่ทราบ | O39: ไม่ทราบ | R39: 3564019.6 | S39: ข้อมูลเก่าเกิน 48 ชม. | T39: FALSE | U39: 2026-10-03T14:57:33+07:00 | V39: https://api-v3.thaiwater.net/api/v1/thaiwater30/public/canal_waterlevel | W39: {"canal_datetime":"2019-12-24 14:38","canal_value":-0.164,"canal_out":0,"agency":{"agency_name":{"th":"สำนักการระบายน้ำ กรุงเทพมหานคร","en":"Department of Bangkok","jp":""}},"geocode":{"area_code":"1","area_name":{"th":"กรุงเทพมหานคร","en":"Bangkok"},"amphoe_name":{"th":"ปทุมวัน","en":"Pathum Wan District"},"tumbon_name":{"th":"รองเมือง","en":"Rong Mueang"},"province_code":"10","province_name":{"th":"กรุงเทพมหานคร","en":"Bangkok"}},"station":{"id":5,"canal_name":{"th":"คลองแสนแสบ ช่วง ค.ผดุงกรุงเกษม (โบ้เบ้)"},"canal_lat":13.752819,"canal_long":100.517188,"canal_oldcode":"SS01","bank":null,"warning_level":null,"critical_level":null}}
A40: THAIWATER:10 | B40: PL01 | C40: คลองพิทยาลงกรณ์ ช่วง ร.ร.พิทยาลงกรณ์ | D40: บางขุนเทียน | F40: 13.528701 | G40: 100.41762 | H40: 2019-12-24T14:38:00+07:00 | I40: 0.414 | N40: ไม่ทราบ | O40: ไม่ทราบ | R40: 3564019.6 | S40: ข้อมูลเก่าเกิน 48 ชม. | T40: FALSE | U40: 2026-10-03T14:57:33+07:00 | V40: https://api-v3.thaiwater.net/api/v1/thaiwater30/public/canal_waterlevel | W40: {"canal_datetime":"2019-12-24 14:38","canal_value":0.414,"canal_out":0,"agency":{"agency_name":{"th":"สำนักการระบายน้ำ กรุงเทพมหานคร","en":"Department of Bangkok","jp":""}},"geocode":{"area_code":"1","area_name":{"th":"กรุงเทพมหานคร","en":"Bangkok"},"amphoe_name":{"th":"บางขุนเทียน","en":"Bang Khun Thian District"},"tumbon_name":{"th":"ท่าข้าม","en":"Tha Kham"},"province_code":"10","province_name":{"th":"กรุงเทพมหานคร","en":"Bangkok"}},"station":{"id":10,"canal_name":{"th":"คลองพิทยาลงกรณ์ ช่วง ร.ร.พิทยาลงกรณ์"},"canal_lat":13.528701,"canal_long":100.417622,"canal_oldcode":"PL01","bank":null,"warning_level":null,"critical_level":null}}
